Workbook

Sheet Tracker
A1: Control | B1: Safeguard | C1: Safeguard Title | D1: Req ID | E1: Requirement | F1: Group | G1: Scope | H1: Check | I1: Not Retroactive | J1: Status | K1: Owner | L1: PR / Ticket | M1: Raised | N1: Verified | O1: Notes
A2: Control 01 — Inventory and Control of Enterprise Assets | B2: 1.1 | C2: Establish and Maintain Detailed Enterprise Asset Inventory | D2: 1.1#1 | E2: Cloud Asset Inventory feed configured at organization scope | F2: CLI + human review | G2: org | H2: V1 | J2: Not started
A3: Control 01 — Inventory and Control of Enterprise Assets | B3: 1.1 | C3: Establish and Maintain Detailed Enterprise Asset Inventory | D3: 1.1#2 | E3: Feed exports to BigQuery or Cloud Storage on a scheduled basis | F3: CLI + human review | G3: org | H3: V2 | J3: Not started
A4: Control 01 — Inventory and Control of Enterprise Assets | B4: 1.1 | C4: Establish and Maintain Detailed Enterprise Asset Inventory | D4: 1.1#3 | E4: All projects enumerated, including those created flat under the org node | F4: CLI + human review | G4: org | H4: V3 | J4: Not started
A5: Control 01 — Inventory and Control of Enterprise Assets | B5: 1.1 | C5: Establish and Maintain Detailed Enterprise Asset Inventory | D5: 1.1#4 | E5: Inventory covers Compute Engine, GKE, Cloud SQL, Cloud Run, Cloud Functions, App Engine, Cloud Storage | F5: CLI + human review | G5: org | H5: V4 | J5: Not started
A6: Control 01 — Inventory and Control of Enterprise Assets | B6: 1.1 | C6: Establish and Maintain Detailed Enterprise Asset Inventory | D6: 1.1#5 | E6: Required labels enforced (owner, environment, cost centre, data classification) | F6: Automated | G6: org | H6: V5 | J6: Not started
A7: Control 01 — Inventory and Control of Enterprise Assets | B7: 1.1 | C7: Establish and Maintain Detailed Enterprise Asset Inventory | D7: 1.1#6 | E7: Shared VPC host and service project relationships mapped | F7: CLI + human review | G7: project | H7: V6 | J7: Not started
A8: Control 01 — Inventory and Control of Enterprise Assets | B8: 1.1 | C8: Establish and Maintain Detailed Enterprise Asset Inventory | D8: 1.1#7 | E8: Inventory reviewed and recertified at least every six months | F8: GCP manual | J8: Not started
A9: Control 01 — Inventory and Control of Enterprise Assets | B9: 1.2 | C9: Address Unauthorized Assets | D9: 1.2#1 | E9: Documented process for resources found without an owner or approval | F9: GCP manual | J9: Not started
A10: Control 01 — Inventory and Control of Enterprise Assets | B10: 1.2 | C10: Address Unauthorized Assets | D10: 1.2#2 | E10: Projects with no billing account or in DELETE_REQUESTED state dispositioned | F10: CLI + human review | G10: project | H10: V7 | J10: Not started
A11: Control 01 — Inventory and Control of Enterprise Assets | B11: 1.2 | C11: Address Unauthorized Assets | D11: 1.2#3 | E11: Orphaned resources reconciled (unattached disks, unused static IPs, idle forwarding rules) | F11: Automated | G11: org | H11: V8 | J11: Not started
A12: Control 01 — Inventory and Control of Enterprise Assets | B12: 1.2 | C12: Address Unauthorized Assets | D12: 1.2#4 | E12: Unlabelled or unattributable resources escalated within a defined window | F12: GCP manual | J12: Not started
A13: Control 01 — Inventory and Control of Enterprise Assets | B13: 1.2 | C13: Address Unauthorized Assets | D13: 1.2#5 | E13: Remediation actions recorded (removed, quarantined, or formally accepted) | F13: GCP manual | J13: Not started
A14: Control 02 — Inventory and Control of Software Assets | B14: 2.1 | C14: Establish and Maintain a Software Inventory | D14: 2.1#1 | E14: VM Manager OS inventory enabled; OS Config agent present on all Compute Engine instances | F14: CLI + human review | G14: project | H14: V9 | J14: Not started
A15: Control 02 — Inventory and Control of Software Assets | B15: 2.1 | C15: Establish and Maintain a Software Inventory | D15: 2.1#2 | E15: Custom image and image family catalogue maintained with build provenance | F15: CLI + human review | G15: project | H15: V10 | J15: Not started
A16: Control 02 — Inventory and Control of Software Assets | B16: 2.1 | C16: Establish and Maintain a Software Inventory | D16: 2.1#3 | E16: Artifact Registry / Container Registry image inventory captured | F16: CLI + human review | G16: project | H16: V11 | J16: Not started
A17: Control 02 — Inventory and Control of Software Assets | B17: 2.1 | C17: Establish and Maintain a Software Inventory | D17: 2.1#4 | E17: GKE cluster and node pool versions recorded | F17: CLI + human review | G17: project | H17: V12 | J17: Not started
A18: Control 02 — Inventory and Control of Software Assets | B18: 2.1 | C18: Establish and Maintain a Software Inventory | D18: 2.1#5 | E18: Cloud Functions, Cloud Run, and App Engine runtime versions recorded | F18: CLI + human review | G18: project | H18: V13 | J18: Not started
A19: Control 02 — Inventory and Control of Software Assets | B19: 2.1 | C19: Establish and Maintain a Software Inventory | D19: 2.1#6 | E19: Cloud SQL engine and version recorded per instance | F19: CLI + human review | G19: project | H19: V14 | J19: Not started
A20: Control 02 — Inventory and Control of Software Assets | B20: 2.1 | C20: Establish and Maintain a Software Inventory | D20: 2.1#7 | E20: Inventory refreshed automatically, not by manual survey | F20: Process & people | J20: Not started
A21: Control 02 — Inventory and Control of Software Assets | B21: 2.2 | C21: Ensure Authorized Software is Currently Supported | D21: 2.2#1 | E21: No instances running end-of-life guest OS (CentOS 7, Debian 9/10, out-of-window Ubuntu) | F21: Automated | G21: org | H21: V15 | J21: Not started
A22: Control 02 — Inventory and Control of Software Assets | B22: 2.2 | C22: Ensure Authorized Software is Currently Supported | D22: 2.2#2 | E22: No GKE clusters on versions past end-of-life; all enrolled in a release channel | F22: Automated | G22: project | H22: V16 | J22: Not started
A23: Control 02 — Inventory and Control of Software Assets | B23: 2.2 | C23: Ensure Authorized Software is Currently Supported | D23: 2.2#3 | E23: No Cloud Functions or App Engine services on decommissioned runtimes | F23: CLI + human review | G23: project | H23: V17 | J23: Not started
A24: Control 02 — Inventory and Control of Software Assets | B24: 2.2 | C24: Ensure Authorized Software is Currently Supported | D24: 2.2#4 | E24: No Cloud SQL instances on unsupported database versions | F24: CLI + human review | G24: project | H24: V18 | J24: Not started
A25: Control 02 — Inventory and Control of Software Assets | B25: 2.2 | C25: Ensure Authorized Software is Currently Supported | D25: 2.2#5 | E25: Deprecated custom images not referenced by any instance template or MIG | F25: CLI + human review | G25: project | H25: V19 | J25: Not started
A26: Control 02 — Inventory and Control of Software Assets | B26: 2.2 | C26: Ensure Authorized Software is Currently Supported | D26: 2.2#6 | E26: Exception register for unsupported software with documented compensating controls | F26: Process & people | J26: Not started
A27: Control 02 — Inventory and Control of Software Assets | B27: 2.3 | C27: Address Unauthorized Software | D27: 2.3#1 | E27: Documented process for removing unapproved software from the environment | F27: Process & people | J27: Not started
A28: Control 02 — Inventory and Control of Software Assets | B28: 2.3 | C28: Address Unauthorized Software | D28: 2.3#2 | E28: Marketplace deployment restricted to approved solutions | F28: Process & people | J28: Not started
A29: Control 02 — Inventory and Control of Software Assets | B29: 2.3 | C29: Address Unauthorized Software | D29: 2.3#3 | E29: Container images sourced only from approved registries | F29: CLI + human review | G29: project | H29: V20 | J29: Not started
A30: Control 02 — Inventory and Control of Software Assets | B30: 2.3 | C30: Address Unauthorized Software | D30: 2.3#4 | E30: Binary Authorization policy in place for GKE / Cloud Run (or a documented equivalent gate) | F30: CLI + human review | G30: project | H30: V21 | J30: Not started
A31: Control 02 — Inventory and Control of Software Assets | B31: 2.3 | C31: Address Unauthorized Software | D31: 2.3#5 | E31: workloads already running unattested identified and rolled | F31: CLI + human review | G31: project | H31: V22 | I31: Yes | J31: Not started
A32: Control 02 — Inventory and Control of Software Assets | B32: 2.3 | C32: Address Unauthorized Software | D32: 2.3#6 | E32: Findings tracked to closure with a defined remediation window | F32: Process & people | J32: Not started
A33: Control 03 — Data Protection | B33: 3.1 | C33: Establish and Maintain a Data Management Process | D33: 3.1#1 | E33: Written data management process covering sensitivity, ownership, handling, retention, disposal | F33: Process & people | J33: Not started
A34: Control 03 — Data Protection | B34: 3.1 | C34: Establish and Maintain a Data Management Process | D34: 3.1#2 | E34: Process references GCP storage services in use | F34: Process & people | J34: Not started
A35: Control 03 — Data Protection | B35: 3.1 | C35: Establish and Maintain a Data Management Process | D35: 3.1#3 | E35: Data residency requirements defined and mapped to regions | F35: CLI + human review | G35: org | H35: V23 | J35: Not started
A36: Control 03 — Data Protection | B36: 3.1 | C36: Establish and Maintain a Data Management Process | D36: 3.1#4 | E36: Reviewed annually with review date recorded | F36: Process & people | J36: Not started
A37: Control 03 — Data Protection | B37: 3.2 | C37: Establish and Maintain a Data Inventory | D37: 3.2#1 | E37: Sensitive Data Protection (Cloud DLP) discovery configured across Cloud Storage and BigQuery | F37: CLI + human review | G37: project | H37: V24 | J37: Not started
A38: Control 03 — Data Protection | B38: 3.2 | C38: Establish and Maintain a Data Inventory | D38: 3.2#2 | E38: Cloud SQL and other data stores included in the inventory | F38: GCP manual | J38: Not started
A39: Control 03 — Data Protection | B39: 3.2 | C39: Establish and Maintain a Data Inventory | D39: 3.2#3 | E39: Sensitivity classification recorded as resource labels or in a central register | F39: Automated | G39: org | H39: V25 | J39: Not started
A40: Control 03 — Data Protection | B40: 3.2 | C40: Establish and Maintain a Data Inventory | D40: 3.2#4 | E40: Data location recorded per store for residency verification | F40: CLI + human review | G40: org | H40: V26 | J40: Not started
...

Sheet Summary
A1: How to use this tracker
A2: Every figure below is a formula over the Tracker tab. Update Status there; this recalculates.
A4: Overall
A5: Total requirements | B5: =COUNTA(Tracker!D2:D291) -> 290
A6: Not started | B6: =COUNTIF(Tracker!$J$2:$J$291,A6) -> 290 | C6: =IFERROR(B6/$B$5,0) -> 1
A7: In progress | B7: =COUNTIF(Tracker!$J$2:$J$291,A7) -> 0 | C7: =IFERROR(B7/$B$5,0) -> 0
A8: PR submitted | B8: =COUNTIF(Tracker!$J$2:$J$291,A8) -> 0 | C8: =IFERROR(B8/$B$5,0) -> 0
A9: Compliant | B9: =COUNTIF(Tracker!$J$2:$J$291,A9) -> 0 | C9: =IFERROR(B9/$B$5,0) -> 0
A10: N/A | B10: =COUNTIF(Tracker!$J$2:$J$291,A10) -> 0 | C10: =IFERROR(B10/$B$5,0) -> 0
A11: Compliant % | B11: =IFERROR(COUNTIF(Tracker!$J$2:$J$291,"Compliant")/$B$5,0) -> 0
A13: By verification group
A14: Group | B14: Total | C14: Compliant | D14: % done
A15: Automated | B15: =COUNTIF(Tracker!$F$2:$F$291,A15) -> 41 | C15: =COUNTIFS(Tracker!$F$2:$F$291,A15,Tracker!$J$2:$J$291,"Compliant") -> 0 | D15: =IFERROR(C15/B15,0) -> 0
A16: CLI + human review | B16: =COUNTIF(Tracker!$F$2:$F$291,A16) -> 147 | C16: =COUNTIFS(Tracker!$F$2:$F$291,A16,Tracker!$J$2:$J$291,"Compliant") -> 0 | D16: =IFERROR(C16/B16,0) -> 0
A17: GCP manual | B17: =COUNTIF(Tracker!$F$2:$F$291,A17) -> 30 | C17: =COUNTIFS(Tracker!$F$2:$F$291,A17,Tracker!$J$2:$J$291,"Compliant") -> 0 | D17: =IFERROR(C17/B17,0) -> 0
A18: Process & people | B18: =COUNTIF(Tracker!$F$2:$F$291,A18) -> 72 | C18: =COUNTIFS(Tracker!$F$2:$F$291,A18,Tracker!$J$2:$J$291,"Compliant") -> 0 | D18: =IFERROR(C18/B18,0) -> 0
A20: By scope
A21: Scope | B21: Total | C21: Compliant | D21: % done
A22: org | B22: =COUNTIF(Tracker!$G$2:$G$291,A22) -> 67 | C22: =COUNTIFS(Tracker!$G$2:$G$291,A22,Tracker!$J$2:$J$291,"Compliant") -> 0 | D22: =IFERROR(C22/B22,0) -> 0
A23: project | B23: =COUNTIF(Tracker!$G$2:$G$291,A23) -> 91 | C23: =COUNTIFS(Tracker!$G$2:$G$291,A23,Tracker!$J$2:$J$291,"Compliant") -> 0 | D23: =IFERROR(C23/B23,0) -> 0
A25: Where the work is sitting
A26: Outstanding with engineering | B26: =COUNTIF(Tracker!$J$2:$J$291,"Not started")+COUNTIF(Tracker!$J$2:$J$291,"In progress") -> 290
A27: Awaiting management approval | B27: =COUNTIF(Tracker!$J$2:$J$291,"PR submitted") -> 0
A28: Done | B28: =COUNTIF(Tracker!$J$2:$J$291,"Compliant") -> 0
A29: Not applicable | B29: =COUNTIF(Tracker!$J$2:$J$291,"N/A") -> 0
A30: A PR sitting unapproved is a management decision, not an engineering backlog item.
A32: By safeguard
A33: Safeguard | B33: Requirements | C33: Compliant | D33: Safeguard met?
A34: 1.1 | B34: =COUNTIF(Tracker!$B$2:$B$291,A34) -> 7 | C34: =COUNTIFS(Tracker!$B$2:$B$291,A34,Tracker!$J$2:$J$291,"Compliant") -> 0 | D34: =IF(B34=C34,"MET","not met") -> not met
A35: 1.2 | B35: =COUNTIF(Tracker!$B$2:$B$291,A35) -> 5 | C35: =COUNTIFS(Tracker!$B$2:$B$291,A35,Tracker!$J$2:$J$291,"Compliant") -> 0 | D35: =IF(B35=C35,"MET","not met") -> not met
A36: 2.1 | B36: =COUNTIF(Tracker!$B$2:$B$291,A36) -> 7 | C36: =COUNTIFS(Tracker!$B$2:$B$291,A36,Tracker!$J$2:$J$291,"Compliant") -> 0 | D36: =IF(B36=C36,"MET","not met") -> not met
A37: 2.2 | B37: =COUNTIF(Tracker!$B$2:$B$291,A37) -> 6 | C37: =COUNTIFS(Tracker!$B$2:$B$291,A37,Tracker!$J$2:$J$291,"Compliant") -> 0 | D37: =IF(B37=C37,"MET","not met") -> not met
A38: 2.3 | B38: =COUNTIF(Tracker!$B$2:$B$291,A38) -> 6 | C38: =COUNTIFS(Tracker!$B$2:$B$291,A38,Tracker!$J$2:$J$291,"Compliant") -> 0 | D38: =IF(B38=C38,"MET","not met") -> not met
A39: 3.1 | B39: =COUNTIF(Tracker!$B$2:$B$291,A39) -> 4 | C39: =COUNTIFS(Tracker!$B$2:$B$291,A39,Tracker!$J$2:$J$291,"Compliant") -> 0 | D39: =IF(B39=C39,"MET","not met") -> not met
A40: 3.2 | B40: =COUNTIF(Tracker!$B$2:$B$291,A40) -> 5 | C40: =COUNTIFS(Tracker!$B$2:$B$291,A40,Tracker!$J$2:$J$291,"Compliant") -> 0 | D40: =IF(B40=C40,"MET","not met") -> not met
A41: 3.3 | B41: =COUNTIF(Tracker!$B$2:$B$291,A41) -> 11 | C41: =COUNTIFS(Tracker!$B$2:$B$291,A41,Tracker!$J$2:$J$291,"Compliant") -> 0 | D41: =IF(B41=C41,"MET","not met") -> not met
A42: 3.4 | B42: =COUNTIF(Tracker!$B$2:$B$291,A42) -> 6 | C42: =COUNTIFS(Tracker!$B$2:$B$291,A42,Tracker!$J$2:$J$291,"Compliant") -> 0 | D42: =IF(B42=C42,"MET","not met") -> not met
A43: 3.5 | B43: =COUNTIF(Tracker!$B$2:$B$291,A43) -> 6 | C43: =COUNTIFS(Tracker!$B$2:$B$291,A43,Tracker!$J$2:$J$291,"Compliant") -> 0 | D43: =IF(B43=C43,"MET","not met") -> not met
A44: 4.1 | B44: =COUNTIF(Tracker!$B$2:$B$291,A44) -> 7 | C44: =COUNTIFS(Tracker!$B$2:$B$291,A44,Tracker!$J$2:$J$291,"Compliant") -> 0 | D44: =IF(B44=C44,"MET","not met") -> not met
A45: 4.2 | B45: =COUNTIF(Tracker!$B$2:$B$291,A45) -> 9 | C45: =COUNTIFS(Tracker!$B$2:$B$291,A45,Tracker!$J$2:$J$291,"Compliant") -> 0 | D45: =IF(B45=C45,"MET","not met") -> not met
...

Sheet How to use
A4: Where to type | B4: Only the shaded columns on the Tracker tab: Status, Owner, PR / Ticket, Raised, Verified, Notes. Everything to their left is generated from the repository and will be overwritten if the tracker is regenerated.
A6: Status values | B6: Not started · In progress · PR submitted · Compliant · N/A
A7: Compliant | B7: Means verified in the live estate. Not 'merged', not 'applied' — verified. A merged PR nobody confirmed is still 'PR submitted'.
A8: PR submitted | B8: The fix is written and raised. The item is now waiting on management approval, not on engineering. Put the PR number in the PR / Ticket column and the date in Raised.
A9: N/A | B9: The product or service does not exist in this organization. Use sparingly — 'we never built a log bucket' is a failure, not an N/A.
A11: Group | B11: How the requirement gets checked:
A12: Automated | B12: audit-run.go runs it and scores pass/fail. 41 requirements.
A13: CLI + human review | B13: audit-run.go runs it and saves the output; a person judges the result. 147 requirements.
A14: GCP manual | B14: A GCP task with no CLI — Admin Console, image build, or a test to perform. 30 requirements.
A15: Process & people | B15: Answered by a conversation and a document, not a command. 72 requirements.
A17: Scope | B17: org = checked once for the whole organization. project = checked once per project.
A18: Check | B18: The V-number in docs/cis-ig1-cli-validation.md holding the command and its pass criteria.
... A21: Scope boundary | B21: These 290 requirements are the GCP-actionable half of IG1. Twelve IG1 safeguards — security awareness training, end-user devices, removable media — have no GCP surface, are not in this sheet, and are owned elsewhere. 100% here is not 100% IG1.
